Workbook

Sheet US DATA
A1: APP.OQ | B1: EPAM.N | C1: LULU.OQ | D1: EXR.N | E1: ERIE.OQ | F1: ACGL.OQ | G1: TPL.N | H1: BLDR.N | I1: SW.N | J1: HII.N | K1: EL.N | L1: DXCM.OQ | M1: REGN.OQ | N1: AIZ.N | O1: DECK.N | P1: NEE.N | Q1: MOH.N | R1: SBAC.OQ | S1: ODFL.OQ | T1: SMCI.OQ | U1: EXPD.N | V1: SYY.N | W1: HST.OQ | X1: FCX.N | Y1: PLTR.OQ | Z1: AXP.N | AA1: JNJ.N | AB1: SPG.N | AC1: L.N | AD1: OXY.N | AE1: OMC.N | AF1: WYNN.OQ | AG1: MGM.N | AH1: MAR.OQ | AI1: WFC.N | AJ1: DTE.N | AK1: MCHP.OQ | AL1: MRNA.OQ | AM1: BRKb.N | AN1: COP.N
A3: =_xll.RDP.Data($A$1:$T$1,"TR.PriceClose","SDate=2025-11-21 EDate=2026-01-31 CH=IN RH=date",B4) -> #N/A | V3: =_xll.RDP.Data($U$1:$AN$1,"TR.PriceClose","SDate=2025-11-21 EDate=2026-01-31 CH=IN RH=date",W4) -> #N/A
C4: APP.OQ | D4: EPAM.N | E4: LULU.OQ | F4: EXR.N | G4: ERIE.OQ | H4: ACGL.OQ | I4: TPL.N | J4: BLDR.N | K4: SW.N | L4: HII.N | M4: EL.N | N4: DXCM.OQ | O4: REGN.OQ | P4: AIZ.N | Q4: DECK.N | R4: NEE.N | S4: MOH.N | T4: SBAC.OQ | U4: ODFL.OQ | V4: SMCI.OQ | X4: EXPD.N | Y4: SYY.N | Z4: HST.OQ | AA4: FCX.N | AB4: PLTR.OQ | AC4: AXP.N | AD4: JNJ.N | AE4: SPG.N | AF4: L.N | AG4: OXY.N | AH4: OMC.N | AI4: WYNN.OQ | AJ4: MGM.N | AK4: MAR.OQ | AL4: WFC.N | AM4: DTE.N | AN4: MCHP.OQ | AO4: MRNA.OQ | AP4: BRKb.N | AQ4: COP.N
B5: 45982 | C5: 520.26 | D5: 180.98 | E5: 168.18 | F5: 131.46 | G5: 296.36 | H5: 92.46 | I5: 298.8097 | J5: 101.62 | K5: 33.78 | L5: 305.49 | M5: 89.9 | N5: 60.23 | O5: 755.9 | P5: 226.82 | Q5: 85.13 | R5: 83.48 | S5: 141.56 | T5: 195.02 | U5: 134.28 | V5: 32.19 | W5: 45982 | X5: 143.21 | Y5: 76.63 | Z5: 17.277139 | AA5: 39.87 | AB5: 154.85 | AC5: 352.89 | AD5: 203.9 | AE5: 183.08 | AF5: 106.4 | AG5: 41.44 | AH5: 74.87 | AI5: 119.6 | AJ5: 32.55 | AK5: 295.84 | AL5: 83.11 | AM5: 135.77 | AN5: 50.9 | AO5: 23.72 | AP5: 504.04 | AQ5: 87.37
B6: 45985 | C6: 559.8 | D6: 183.23 | E6: 169.67 | F6: 130.35 | G6: 291.92 | H6: 91.94 | I6: 292.23971 | J6: 100.53 | K6: 33.71 | L6: 309.92 | M6: 93.39 | N6: 62.21 | O6: 761.45 | P6: 226.02 | Q6: 83.13 | R6: 84.23 | S6: 145.3 | T6: 193.09 | U6: 132.33 | V6: 33.32 | W6: 45985 | X6: 144.26 | Y6: 74.7 | Z6: 17.187877 | AA6: 40.79 | AB6: 162.25 | AC6: 355.93 | AD6: 206.05 | AE6: 182.66 | AF6: 107.2 | AG6: 41.43 | AH6: 74.83 | AI6: 123.24 | AJ6: 32.38 | AK6: 296.23 | AL6: 84.66 | AM6: 136.07 | AN6: 51.25 | AO6: 24.15 | AP6: 507.81 | AQ6: 87.56
B7: 45986 | C7: 556.03 | D7: 185.8 | E7: 177.51 | F7: 132.37 | G7: 295.63 | H7: 93.61 | I7: 288.13638 | J7: 108.97 | K7: 34.96 | L7: 314.73 | M7: 91.94 | N7: 61.69 | O7: 787.32 | P7: 228.17 | Q7: 85.47 | R7: 84.83 | S7: 146.77 | T7: 193.3 | U7: 134.33 | V7: 32.48 | W7: 45986 | X7: 147.58 | Y7: 75.91 | Z7: 17.644104 | AA7: 41.07 | AB7: 163.55 | AC7: 362.64 | AD7: 206.67 | AE7: 185.13 | AF7: 107.95 | AG7: 41.41 | AH7: 72.85 | AI7: 127.47 | AJ7: 34.14 | AK7: 304.12 | AL7: 85.1 | AM7: 136.07 | AN7: 51.83 | AO7: 24.75 | AP7: 508.57 | AQ7: 86.62
B8: 45987 | C8: 586.37 | D8: 184.69 | E8: 181.94 | F8: 133.29 | G8: 294.24 | H8: 94.4 | I8: 287.63638 | J8: 111.75 | K8: 35.78 | L8: 314.31 | M8: 93.7 | N8: 62.53 | O8: 784.61 | P8: 228.52 | Q8: 87.19 | R8: 85.54 | S8: 148.33 | T8: 194.79 | U8: 134.91 | V8: 32.83 | W8: 45987 | X8: 147.36 | Y8: 75.9 | Z8: 17.594514 | AA8: 42.15 | AB8: 165.77 | AC8: 363.97 | AD8: 207.56 | AE8: 185.56 | AF8: 108.26 | AG8: 41.42 | AH8: 71.5 | AI8: 129.46 | AJ8: 34.78 | AK8: 304.65 | AL8: 85.56 | AM8: 136.78 | AN8: 52.57 | AO8: 25.01 | AP8: 511.23 | AQ8: 87.09
B9: 45989 | C9: 599.48 | D9: 187 | E9: 184.18 | F9: 133.17 | G9: 295.49 | H9: 93.92 | I9: 288.09638 | J9: 112.23 | K9: 35.69 | L9: 313.62 | M9: 94.07 | N9: 63.47 | O9: 780.19 | P9: 228.16 | Q9: 88.03 | R9: 86.29 | S9: 148.26 | T9: 194.27 | U9: 135.29 | V9: 33.85 | W9: 45989 | X9: 146.9 | Y9: 76.2 | Z9: 17.485416 | AA9: 42.98 | AB9: 168.45 | AC9: 365.27 | AD9: 206.92 | AE9: 186.32 | AF9: 107.87 | AG9: 42 | AH9: 71.62 | AI9: 128.68 | AJ9: 35.29 | AK9: 304.79 | AL9: 85.85 | AM9: 137.03 | AN9: 53.58 | AO9: 25.98 | AP9: 513.81 | AQ9: 88.69
B10: 45992 | C10: 623.59 | D10: 190.42 | E10: 182.41 | F10: 131.94 | G10: 293.76 | H10: 93.16 | I10: 284.57972 | J10: 113.18 | K10: 35.65 | L10: 306.65 | M10: 94.71 | N10: 63.52 | O10: 750.11 | P10: 225.43 | Q10: 92.02 | R10: 84.65 | S10: 145 | T10: 188.57 | U10: 139.67 | V10: 33.41 | W10: 45992 | X10: 146.45 | Y10: 75.91 | Z10: 17.406072 | AA10: 43.07 | AB10: 167.49 | AC10: 360.31 | AD10: 205.34 | AE10: 185.14 | AF10: 106.4 | AG10: 42.34 | AH10: 72.01 | AI10: 132.77 | AJ10: 35.44 | AK10: 303.44 | AL10: 85.4 | AM10: 133.27 | AN10: 53.43 | AO10: 24.16 | AP10: 508.55 | AQ10: 90.26
B11: 45993 | C11: 653 | D11: 192.99 | E11: 182.4 | F11: 132.52 | G11: 295.95 | H11: 92.69 | I11: 288.22305 | J11: 112.1 | K11: 34.45 | L11: 307.2 | M11: 99.64 | N11: 64.45 | O11: 742 | P11: 221.37 | Q11: 91.77 | R11: 84.58 | S11: 145.97 | T11: 186.97 | U11: 141.46 | V11: 32.92 | W11: 45993 | X11: 146.48 | Y11: 74.44 | Z11: 17.386236 | AA11: 42.97 | AB11: 170.69 | AC11: 360.7 | AD11: 205.42 | AE11: 182.17 | AF11: 106.31 | AG11: 41.98 | AH11: 72.47 | AI11: 133.09 | AJ11: 35.34 | AK11: 304.65 | AL11: 86.32 | AM11: 131.55 | AN11: 56.71 | AO11: 24.06 | AP11: 506.65 | AQ11: 89.29
B12: 45994 | C12: 662.21 | D12: 200 | E12: 182.3 | F12: 132.24 | G12: 296.21 | H12: 92.72 | I12: 304.90636 | J12: 114.44 | K12: 36.12 | L12: 309.23 | M12: 102.03 | N12: 64.85 | O12: 723.67 | P12: 222.33 | Q12: 94.97 | R12: 84.95 | S12: 149.09 | T12: 187.34 | U12: 150.945 | V12: 33.68 | W12: 45994 | X12: 148.09 | Y12: 73.36 | Z12: 17.51517 | AA12: 44.53 | AB12: 176.08 | AC12: 368.13 | AD12: 205.33 | AE12: 182.3 | AF12: 105.75 | AG12: 42.45 | AH12: 71 | AI12: 131.53 | AJ12: 35.54 | AK12: 306.65 | AL12: 89.35 | AM12: 133.18 | AN12: 63.61 | AO12: 25.18 | AP12: 503.6 | AQ12: 91.81
B13: 45995 | C13: 683.78 | D13: 201.5 | E13: 183.6 | F13: 131.09 | G13: 299.78 | H13: 92.39 | I13: 306.58303 | J13: 111.01 | K13: 36.45 | L13: 315.88 | M13: 103.82 | N13: 65.25 | O13: 722.8 | P13: 224.27 | Q13: 96.25 | R13: 83.39 | S13: 150.57 | T13: 190 | U13: 153.51 | V13: 34.23 | W13: 45995 | X13: 150.5 | Y13: 73.44 | Z13: 17.019271 | AA13: 44.61 | AB13: 177.92 | AC13: 371.15 | AD13: 202.48 | AE13: 183.32 | AF13: 104.49 | AG13: 42.67 | AH13: 70.17 | AI13: 125.72 | AJ13: 35.39 | AK13: 296 | AL13: 90.21 | AM13: 132.16 | AN13: 64.72 | AO13: 25.49 | AP13: 503.23 | AQ13: 93.12
B14: 45996 | C14: 691.94 | D14: 203.6 | E14: 190.01 | F14: 129.56 | G14: 296.46 | H14: 91.72 | I14: 308.35969 | J14: 110.01 | K14: 36.04 | L14: 304.58 | M14: 105.13 | N14: 65.49 | O14: 718.36 | P14: 222.87 | Q14: 99.7 | R14: 83.13 | S14: 151.86 | T14: 189.58 | U14: 155.15 | V14: 34.69 | W14: 45996 | X14: 151.47 | Y14: 73.1 | Z14: 17.118451 | AA14: 45.2 | AB14: 181.76 | AC14: 370.35 | AD14: 201.93 | AE14: 182.56 | AF14: 102.82 | AG14: 42.43 | AH14: 73.44 | AI14: 125.51 | AJ14: 36.07 | AK14: 292.59 | AL14: 89.83 | AM14: 131.23 | AN14: 65.81 | AO14: 27.7 | AP14: 504.34 | AQ14: 93.69
B15: 45999 | C15: 689.76 | D15: 203.64 | E15: 183.04 | F15: 128.54 | G15: 280.81 | H15: 90.94 | I15: 301.38303 | J15: 107.46 | K15: 36.06 | L15: 315.88 | M15: 102.78 | N15: 65.62 | O15: 703.26 | P15: 221.76 | Q15: 101.21 | R15: 80.55 | S15: 155.51 | T15: 190.98 | U15: 151.68 | V15: 35.37 | W15: 45999 | X15: 148.05 | Y15: 72.71 | Z15: 16.959763 | AA15: 45 | AB15: 181.49 | AC15: 362.28 | AD15: 201.62 | AE15: 180.07 | AF15: 101.41 | AG15: 41.36 | AH15: 73.15 | AI15: 127.13 | AJ15: 35.32 | AK15: 287.82 | AL15: 90.06 | AM15: 130 | AN15: 67.35 | AO15: 27.97 | AP15: 497.23 | AQ15: 92.88
B16: 46000 | C16: 724.62 | D16: 207.97 | E16: 182.28 | F16: 126.69 | G16: 277.4 | H16: 91.92 | I16: 293.60637 | J16: 105.01 | K16: 35.31 | L16: 314.95 | M16: 102.64 | N16: 66.33 | O16: 692.58 | P16: 222.4 | Q16: 100.81 | R16: 79.64 | S16: 156.88 | T16: 189.29 | U16: 148.89 | V16: 35.02 | W16: 46000 | X16: 147.71 | Y16: 72.59 | Z16: 17.306893 | AA16: 44.8 | AB16: 181.84 | AC16: 363.91 | AD16: 199.96 | AE16: 181.05 | AF16: 102.56 | AG16: 41.55 | AH16: 73.24 | AI16: 124.22 | AJ16: 35.89 | AK16: 283.84 | AL16: 88.89 | AM16: 130.25 | AN16: 66.85 | AO16: 28.24 | AP16: 491.43 | AQ16: 93.43
... B51: 46052 | C51: 473.11 | D51: 208.6 | E51: 174.5 | F51: 137.97 | G51: 283.01 | H51: 96.04 | I51: 348.36 | J51: 114.4 | K51: 41.63 | L51: 420.51 | M51: 115.28 | N51: 73.04 | O51: 741.45 | P51: 238.13 | Q51: 119.34 | R51: 87.9 | S51: 179.59 | T51: 184.11 | U51: 173.2 | V51: 29.11 | W51: 46052 | X51: 160.54 | Y51: 83.85 | Z51: 18.53 | AA51: 60.23 | AB51: 146.59 | AC51: 352.17 | AD51: 227.25 | AE51: 191.31 | AF51: 105.57 | AG51: 45.39 | AH51: 77.04 | AI51: 107.45 | AJ51: 33.54 | AK51: 315.3 | AL51: 90.49 | AM51: 134.38 | AN51: 75.92 | AO51: 44.07 | AP51: 480.53 | AQ51: 104.23
A245: =_xll.RDP.Data("SNPS.O","TR.PriceClose","SDate=2025-04-28 EDate=2025-11-21 Curn=EUR CH=IN RH=date",B246) -> #N/A
C246: SNPS.O
B247: 45775 | C247: 388.73125
B248: 45776 | C248: 404.71733
B249: 45777 | C249: 405.23698
B250: 45778 | C250: 406.83678
B251: 45779 | C251: 418.1331
B252: 45782 | C252: 421.9636
B253: 45783 | C253: 416.56299
B254: 45784 | C254: 425.29232
B255: 45785 | C255: 431.54899
B256: 45786 | C256: 429.36088
B257: 45789 | C257: 456.02196
B258: 45790 | C258: 461.11178
... B392: 45982 | C392: 337.37998

Sheet EU DATA
A1: FBK.MI | B1: REDE.MC | C1: EVOG.ST | D1: EQTAB.ST | E1: PRY.MI | F1: CCL.L | G1: STERV.HE | H1: HEM.ST | I1: NESTE.HE | J1: LAGRb.ST | K1: LIFCOb.ST | L1: SAGAb.ST | M1: SSABb.ST | N1: HAGG.DE | O1: BALDb.ST | P1: MYCR.ST | Q1: URW.PA | R1: VALMT.HE | S1: R3NK.DE | T1: DNP.WA | U1: SYENS.BR | V1: RKT.L | W1: GALD.S | X1: DTGGe.DE | Y1: RIO.L | Z1: HWDN.L | AA1: PHP.L | AB1: ALLN.S | AC1: INF.L | AD1: ITRK.L | AE1: HSBA.L | AF1: HLN.L | AG1: KPN.AS | AH1: MOBN.S | AI1: SCMN.S | AJ1: WISEa.L | AK1: ULVR.L | AL1: NG.L | AM1: BARC.L | AN1: RR.L
A3: =_xll.RDP.Data($A$1:$T$1,"TR.PriceClose","SDate=2025-11-21 EDate=2026-01-31 CH=IN RH=date",B4) -> #N/A | V3: =_xll.RDP.Data($U$1:$AM$1,"TR.PriceClose","SDate=2025-11-21 EDate=2026-01-31 CH=IN RH=date",W4) -> #N/A
C4: FBK.MI | D4: REDE.MC | E4: EVOG.ST | F4: EQTAB.ST | G4: PRY.MI | H4: CCL.L | I4: STERV.HE | J4: HEM.ST | K4: NESTE.HE | L4: LAGRb.ST | M4: LIFCOb.ST | N4: SAGAb.ST | O4: SSABb.ST | P4: HAGG.DE | Q4: BALDb.ST | R4: MYCR.ST | S4: URW.PA | T4: VALMT.HE | U4: R3NK.DE | V4: DNP.WA | X4: SYENS.BR | Y4: RKT.L | Z4: GALD.S | AA4: DTGGe.DE | AB4: RIO.L | AC4: HWDN.L | AD4: PHP.L | AE4: ALLN.S | AF4: INF.L | AG4: ITRK.L | AH4: HSBA.L | AI4: HLN.L | AJ4: KPN.AS | AK4: MOBN.S | AL4: SCMN.S | AM4: WISEa.L | AN4: ULVR.L | AO4: NG.L | AP4: BARC.L
B5: 45982 | C5: 20.61 | D5: 15.04 | E5: 632 | F5: 314 | G5: 80.8 | H5: 1808.5 | I5: 9.654 | J5: 175.1 | K5: 16.725 | L5: 207.2 | M5: 342.2 | N5: 198.9 | O5: 61.32 | P5: 72.5 | Q5: 67.52 | R5: 202.75 | S5: 89.4 | T5: 27.55 | U5: 50.86 | V5: 42.3 | W5: 45982 | X5: 68.54 | Y5: 5916.7716 | Z5: 147.7 | AA5: 35.55 | AB5: 5308 | AC5: 802 | AD5: 94.3 | AE5: 198.2 | AF5: 918.2 | AG5: 4834 | AH5: 1041.4 | AI5: 377.2 | AJ5: 3.93 | AK5: 354.5 | AL5: 574.5 | AM5: 874 | AN5: 4911.4944 | AO5: 1138.5 | AP5: 392.2
B6: 45985 | C6: 20.52 | D6: 15.22 | E6: 638 | F6: 320.6 | G6: 83 | H6: 1844 | I6: 9.86 | J6: 176.4 | K6: 16.1 | L6: 209 | M6: 343.8 | N6: 199.4 | O6: 63.22 | P6: 69.2 | Q6: 68.06 | R6: 209.1 | S6: 89.46 | T6: 27.78 | U6: 48.635 | V6: 41.96 | W6: 45985 | X6: 69.22 | Y6: 5856.6825 | Z6: 149.7 | AA6: 36.08 | AB6: 5355 | AC6: 811 | AD6: 94.05 | AE6: 199.8 | AF6: 915.8 | AG6: 4870 | AH6: 1048 | AI6: 371.8 | AJ6: 3.94 | AK6: 357 | AL6: 580.5 | AM6: 871 | AN6: 4844.0082 | AO6: 1116 | AP6: 400.6
B7: 45986 | C7: 20.97 | D7: 15.22 | E7: 638.8 | F7: 323.2 | G7: 82.78 | H7: 1800 | I7: 10.04 | J7: 168.2 | K7: 15.965 | L7: 214.2 | M7: 347.2 | N7: 200 | O7: 64.52 | P7: 68.9 | Q7: 67.8 | R7: 208.65 | S7: 90 | T7: 28.21 | U7: 50.91 | V7: 41.99 | W7: 45986 | X7: 70.22 | Y7: 5878.7152 | Z7: 155.3 | AA7: 37.15 | AB7: 5400 | AC7: 834 | AD7: 95.2 | AE7: 199.8 | AF7: 937.6 | AG7: 4592 | AH7: 1050.6 | AI7: 374.5 | AJ7: 3.973 | AK7: 357 | AL7: 582.5 | AM7: 879 | AN7: 4876.1445 | AO7: 1123.5 | AP7: 410
B8: 45987 | C8: 21 | D8: 15.26 | E8: 640 | F8: 329.9 | G8: 85.22 | H8: 1796.5 | I8: 10.005 | J8: 170.1 | K8: 16.5 | L8: 216.6 | M8: 351.2 | N8: 203 | O8: 66.32 | P8: 69 | Q8: 68.38 | R8: 215.6 | S8: 90.72 | T8: 28.12 | U8: 51.35 | V8: 41.81 | W8: 45987 | X8: 69.9 | Y8: 5900.7478 | Z8: 158.6 | AA8: 37.21 | AB8: 5461 | AC8: 834 | AD8: 96.35 | AE8: 200.5 | AF8: 945.6 | AG8: 4638 | AH8: 1064.4 | AI8: 370.8 | AJ8: 3.99 | AK8: 359 | AL8: 585.5 | AM8: 867 | AN8: 4842.937 | AO8: 1134.5 | AP8: 422.95
B9: 45988 | C9: 21.09 | D9: 15.4 | E9: 650 | F9: 330.6 | G9: 85.44 | H9: 1839.5 | I9: 10.165 | J9: 171.2 | K9: 16.72 | L9: 216.4 | M9: 350 | N9: 203 | O9: 65.5 | P9: 69.7 | Q9: 68.42 | R9: 219 | S9: 91.58 | T9: 28.18 | U9: 51.08 | V9: 41.03 | W9: 45988 | X9: 69.86 | Y9: 5882.7211 | Z9: 159.5 | AA9: 37.04 | AB9: 5355 | AC9: 839.5 | AD9: 97.2 | AE9: 201 | AF9: 946.8 | AG9: 4634 | AH9: 1065 | AI9: 370 | AJ9: 3.987 | AK9: 357.5 | AL9: 583.5 | AM9: 870 | AN9: 4841.8658 | AO9: 1144 | AP9: 429.95
B10: 45989 | C10: 21.15 | D10: 15.38 | E10: 645.2 | F10: 327 | G10: 86.3 | H10: 1813.5 | I10: 10.13 | J10: 175.5 | K10: 16.64 | L10: 216.2 | M10: 347.2 | N10: 202 | O10: 66.2 | P10: 68.35 | Q10: 67.92 | R10: 218 | S10: 91.62 | T10: 28.11 | U10: 50.45 | V10: 40.83 | W10: 45989 | X10: 70.26 | Y10: 5860.6884 | Z10: 160 | AA10: 36.47 | AB10: 5422 | AC10: 841 | AD10: 97.5 | AE10: 202 | AF10: 959.8 | AG10: 4626 | AH10: 1070.2 | AI10: 370.9 | AJ10: 3.94 | AK10: 359 | AL10: 576.5 | AM10: 883 | AN10: 4867.5748 | AO10: 1146.5 | AP10: 430.25
B11: 45992 | C11: 20.85 | D11: 15.28 | E11: 653.4 | F11: 320.1 | G11: 84.82 | H11: 1805 | I11: 10.015 | J11: 169.6 | K11: 16.89 | L11: 214.2 | M11: 344.8 | N11: 199.1 | O11: 66.3 | P11: 66.2 | Q11: 67.04 | R11: 216.85 | S11: 91.24 | T11: 27.84 | U11: 48.07 | V11: 40.79 | W11: 45992 | X11: 69.74 | Y11: 6002.8993 | Z11: 158.1 | AA11: 35.99 | AB11: 5465 | AC11: 839.5 | AD11: 97.15 | AE11: 200 | AF11: 946.2 | AG11: 4614 | AH11: 1079.6 | AI11: 374.4 | AJ11: 3.943 | AK11: 361 | AL11: 572.5 | AM11: 876.5 | AN11: 4883.643 | AO11: 1144 | AP11: 429.6
B12: 45993 | C12: 20.73 | D12: 15.29 | E12: 641.2 | F12: 321.1 | G12: 84.76 | H12: 1813 | I12: 9.934 | J12: 165.9 | K12: 17.14 | L12: 213 | M12: 342.2 | N12: 197.2 | O12: 66.2 | P12: 68.15 | Q12: 66.48 | R12: 214.95 | S12: 91.26 | T12: 27.9 | U12: 48.965 | V12: 40.56 | W12: 45993 | X12: 68.62 | Y12: 5988.8785 | Z12: 158.1 | AA12: 35.35 | AB12: 5417 | AC12: 824.5 | AD12: 97.5 | AE12: 201 | AF12: 937.2 | AG12: 4600 | AH12: 1087.8 | AI12: 368.8 | AJ12: 3.956 | AK12: 360.5 | AL12: 568 | AM12: 877 | AN12: 4802.2311 | AO12: 1150.5 | AP12: 436.4
B13: 45994 | C13: 20.55 | D13: 15.24 | E13: 633.4 | F13: 320.8 | G13: 82.6 | H13: 1794.5 | I13: 10.21 | J13: 162 | K13: 17.655 | L13: 213.2 | M13: 344.4 | N13: 195.9 | O13: 66.9 | P13: 68.3 | Q13: 65.62 | R13: 215.8 | S13: 90.14 | T13: 28.28 | U13: 49.225 | V13: 39.4 | W13: 45994 | X13: 68.42 | Y13: 5932.7953 | Z13: 163.2 | AA13: 35.48 | AB13: 5504 | AC13: 817.5 | AD13: 97.45 | AE13: 200.5 | AF13: 947 | AG13: 4600 | AH13: 1070.2 | AI13: 361.1 | AJ13: 3.952 | AK13: 358 | AL13: 562.5 | AM13: 850.5 | AN13: 4770.0948 | AO13: 1143.5 | AP13: 433.35
B14: 45995 | C14: 20.71 | D14: 15.02 | E14: 621.8 | F14: 324 | G14: 84.5 | H14: 1779 | I14: 10.4 | J14: 159.2 | K14: 17.365 | L14: 218.8 | M14: 352.4 | N14: 199.6 | O14: 67.66 | P14: 69.05 | Q14: 66.66 | R14: 221.65 | S14: 90.14 | T14: 28.87 | U14: 49.455 | V14: 38.63 | W14: 45995 | X14: 68.1 | Y14: 5914.7686 | Z14: 163.7 | AA14: 37.63 | AB14: 5494 | AC14: 827.5 | AD14: 97.6 | AE14: 200 | AF14: 940.8 | AG14: 4608 | AH14: 1074.4 | AI14: 359.5 | AJ14: 3.969 | AK14: 357.5 | AL14: 561 | AM14: 849.5 | AN14: 4743.3146 | AO14: 1142.5 | AP14: 439.2
B15: 45996 | C15: 20.4 | D15: 15.2 | E15: 622.4 | F15: 329.8 | G15: 84.98 | H15: 1796.5 | I15: 10.3 | J15: 170.5 | K15: 18.305 | L15: 214.6 | M15: 352.6 | N15: 200.8 | O15: 67.8 | P15: 68.45 | Q15: 66.92 | R15: 219.55 | S15: 89.22 | T15: 28.86 | U15: 51.71 | V15: 38.38 | W15: 45996 | X15: 69.42 | Y15: 5976.8607 | Z15: 162.8 | AA15: 37.65 | AB15: 5500 | AC15: 824.5 | AD15: 96.85 | AE15: 197.4 | AF15: 948.6 | AG15: 4590 | AH15: 1062 | AI15: 360.6 | AJ15: 3.934 | AK15: 351.5 | AL15: 557.5 | AM15: 863.5 | AN15: 4773.3084 | AO15: 1134.5 | AP15: 434.4
B16: 45999 | C16: 20.45 | D16: 15.13 | E16: 630 | F16: 327.9 | G16: 85.96 | H16: 1788.5 | I16: 10.245 | J16: 177.3 | K16: 18.34 | L16: 213.6 | M16: 348.8 | N16: 198.6 | O16: 69 | P16: 69.95 | Q16: 65.54 | R16: 219.7 | S16: 90.74 | T16: 28.64 | U16: 54.57 | V16: 38.14 | W16: 45999 | X16: 69.02 | Y16: 5910.7627 | Z16: 164.5 | AA16: 37.5 | AB16: 5476 | AC16: 808.5 | AD16: 95.35 | AE16: 196.4 | AF16: 941.4 | AG16: 4532 | AH16: 1064.6 | AI16: 357.6 | AJ16: 3.901 | AK16: 351 | AL16: 555.5 | AM16: 861 | AN16: 4680 | AO16: 1135.5 | AP16: 437
... B27: 46014 | C27: 22.07 | D27: 15.18 | E27: 621.2 | F27: 356 | G27: 85.94 | H27: 2343 | I27: 10.315 | J27: 170.9 | K27: 18.885 | L27: 211.4 | M27: 349.4 | N27: 195.3 | O27: 68.44 | P27: 73.2 | Q27: 66.1 | R27: 219.55 | S27: 92.2 | T27: 27.54 | U27: 52.79 | V27: 40.95 | W27: 46014 | X27: 67.5 | Y27: 5994.8874 | Z27: 164.1 | AA27: 37.01 | AB27: 5997 | AC27: 828.5 | AD27: 97.2 | AE27: 203 | AF27: 879.8 | AG27: 4650 | AH27: 1175.2 | AI27: 372.1 | AJ27: 3.952 | AK27: 362 | AL27: 568.5 | AM27: 891 | AN27: 4857.5 | AO27: 1138 | AP27: 471.6
B28: 46020 | C28: 22 | D28: 15.13 | E28: 626.8 | F28: 362.5 | G28: 85.78 | H28: 2235 | I28: 10.595 | J28: 171.8 | K28: 19.24 | L28: 212.6 | M28: 351.8 | N28: 196.6 | O28: 69.3 | P28: 72.5 | Q28: 67.28 | R28: 222.45 | S28: 92.66 | T28: 27.91 | U28: 52.4 | V28: 41.35 | W28: 46015 | X28: 67.88 | Y28: 5986.8755 | Z28: NULL | AA28: NULL | AB28: 5982 | AC28: 831 | AD28: 97.2 | AE28: NULL | AF28: 880.4 | AG28: 4658 | AH28: 1175.4 | AI28: 372.3 | AJ28: 3.949 | AK28: NULL | AL28: NULL | AM28: 893.5 | AN28: 4838 | AO28: 1137.5 | AP28: 469.75
B29: 46021 | C29: 22.2 | D29: 15.19 | E29: 629.8 | F29: 363.8 | G29: 86.38 | H29: 2291 | I29: 10.705 | J29: 173.2 | K29: 19.41 | L29: 212.8 | M29: 352 | N29: 197.6 | O29: 69.66 | P29: 73.4 | Q29: 68.2 | R29: 223.25 | S29: 93.38 | T29: 28.33 | U29: 53.62 | V29: 41.35 | W29: 46020 | X29: 68.32 | Y29: 6006.9052 | Z29: 161.8 | AA29: 37.08 | AB29: 5950 | AC29: 833 | AD29: 97.9 | AE29: 203 | AF29: 882.2 | AG29: 4656 | AH29: 1166 | AI29: 373 | AJ29: 3.971 | AK29: 363 | AL29: 573.5 | AM29: 894 | AN29: 4860 | AO29: 1141 | AP29: 469.25
B30: 46024 | C30: 22.49 | D30: 15.27 | E30: 624.2 | F30: 358.2 | G30: 89.88 | H30: 2274 | I30: 10.82 | J30: 159.9 | K30: 19.92 | L30: 202.2 | M30: 340.8 | N30: 193 | O30: 72.8 | P30: 76.4 | Q30: 67.48 | R30: 216.6 | S30: 92.52 | T30: 28.28 | U30: 55.56 | V30: 41 | W30: 46021 | X30: 69.16 | Y30: 6020.926 | Z30: 162.1 | AA30: 37.32 | AB30: 6026 | AC30: 839.5 | AD30: 98.1 | AE30: 204 | AF30: 888.2 | AG30: 4630 | AH30: 1175.6 | AI30: 373.6 | AJ30: 3.974 | AK30: 366 | AL30: 575.5 | AM30: 894.5 | AN30: 4856 | AO30: 1147.5 | AP30: 476.8
B31: 46027 | C31: 22.71 | D31: 15.31 | E31: 617.8 | F31: 356.9 | G31: 91.54 | H31: 2285 | I31: 10.745 | J31: 160.2 | K31: 20.31 | L31: 204 | M31: 336.4 | N31: 191.5 | O31: 73.58 | P31: 82.65 | Q31: 67.38 | R31: 222.3 | S31: 93.2 | T31: 28.36 | U31: 60.02 | V31: 41.09 | W31: 46022 | X31: 68.56 | Y31: 6010.9111 | Z31: NULL | AA31: NULL | AB31: 5994 | AC31: 832.5 | AD31: 97.9 | AE31: NULL | AF31: 884 | AG31: 4626 | AH31: 1173.8 | AI31: 374.8 | AJ31: 3.976 | AK31: NULL | AL31: NULL | AM31: 891 | AN31: 4859.5 | AO31: 1141.5 | AP31: 475.95
B32: 46028 | C32: 22.83 | D32: 15.38 | E32: NULL | F32: NULL | G32: 90.8 | H32: 2406 | I32: NULL | J32: NULL | K32: NULL | L32: NULL | M32: NULL | N32: NULL | O32: NULL | P32: 82 | Q32: NULL | R32: NULL | S32: 92.76 | T32: NULL | U32: 59.6 | V32: NULL | W32: 46024 | X32: 69.92 | Y32: 5990.8814 | Z32: NULL | AA32: 37.5 | AB32: 5986 | AC32: 839 | AD32: 98.05 | AE32: NULL | AF32: 874 | AG32: 4554 | AH32: 1191.8 | AI32: 370.1 | AJ32: 3.971 | AK32: NULL | AL32: NULL | AM32: 871.5 | AN32: 4822.5 | AO32: 1157.5 | AP32: 479.5
B33: 46029 | C33: 22.54 | D33: 15.4 | E33: 620 | F33: 365.9 | G33: 91.42 | H33: 2339 | I33: 10.745 | J33: 159.6 | K33: 20.02 | L33: 209.2 | M33: 352.4 | N33: 203 | O33: 74.1 | P33: 86.85 | Q33: 71.14 | R33: 228.6 | S33: 94.72 | T33: 29.3 | U33: 61.86 | V33: 42.37 | W33: 46027 | X33: 69.7 | Y33: 5996.8904 | Z33: 160.1 | AA33: 38 | AB33: 6091 | AC33: 836 | AD33: 98 | AE33: 204 | AF33: 884.6 | AG33: 4606 | AH33: 1207.2 | AI33: 372.3 | AJ33: 3.957 | AK33: 366 | AL33: 579 | AM33: 864.5 | AN33: 4699 | AO33: 1150 | AP33: 486.65
B34: 46030 | C34: 22.5 | D34: 15.43 | E34: 614.6 | F34: 351.6 | G34: 87.48 | H34: 2373 | I34: 10.56 | J34: 160.6 | K34: 19.59 | L34: 204.8 | M34: 342.8 | N34: 198.2 | O34: 73.8 | P34: 86.35 | Q34: 69.9 | R34: 211 | S34: 95.14 | T34: 28.92 | U34: 63.67 | V34: 41.44 | W34: 46028 | X34: 72.88 | Y34: 6068.9973 | Z34: 165.6 | AA34: 40.18 | AB34: 6291 | AC34: 832 | AD34: 97.7 | AE34: 203 | AF34: 897 | AG34: 4612 | AH34: 1217.4 | AI34: 376.5 | AJ34: 3.926 | AK34: 363.5 | AL34: 584 | AM34: 867.5 | AN34: 4744 | AO34: 1172 | AP34: 488.4
B35: 46031 | C35: 22.55 | D35: 15.25 | E35: 620 | F35: 360.5 | G35: 87.28 | H35: 2361 | I35: 10.73 | J35: 164.5 | K35: 19.87 | L35: 208.6 | M35: 348.4 | N35: 201.6 | O35: 74.98 | P35: 91.3 | Q35: 71.04 | R35: 212 | S35: 94.24 | T35: 29.36 | U35: 64.18 | V35: 42.2 | W35: 46029 | X35: 72.3 | Y35: 6062.9883 | Z35: 165.2 | AA35: 39.9 | AB35: 6258 | AC35: 839.5 | AD35: 102.2 | AE35: 206.5 | AF35: 893.2 | AG35: 4596 | AH35: 1190.8 | AI35: 373.5 | AJ35: 3.855 | AK35: 370.5 | AL35: 589.5 | AM35: 844.5 | AN35: 4631 | AO35: 1184.5 | AP35: 479.55
B36: 46034 | C36: 22.58 | D36: 15.22 | E36: 620.4 | F36: 361.9 | G36: 85.78 | H36: 2327 | I36: 10.645 | J36: 160.8 | K36: 19.91 | L36: 204.2 | M36: 341.2 | N36: 200.6 | O36: 74.8 | P36: 92 | Q36: 69.74 | R36: 207.15 | S36: 93.86 | T36: 29.33 | U36: 66.22 | V36: 41.99 | W36: 46030 | X36: 71.14 | Y36: 6179.1606 | Z36: 163.2 | AA36: 39.66 | AB36: 6194 | AC36: 841 | AD36: 102.6 | AE36: 207.5 | AF36: 890.4 | AG36: 4618 | AH36: 1195.4 | AI36: 371.9 | AJ36: 3.892 | AK36: 371 | AL36: 590.5 | AM36: 862.5 | AN36: 4665 | AO36: 1183 | AP36: 484.7
B37: 46035 | C37: 22.53 | D37: 14.95 | E37: 611.4 | F37: 360 | G37: 86.28 | H37: 2265 | I37: 10.75 | J37: 162.1 | K37: 20.38 | L37: 202.2 | M37: 330.8 | N37: 198.8 | O37: 78.4 | P37: 92 | Q37: 69.54 | R37: 208.4 | S37: 92.4 | T37: 29.12 | U37: 64.96 | V37: 42.18 | W37: 46031 | X37: 71 | Y37: 6185.1695 | Z37: 165.2 | AA37: 39.91 | AB37: 6006 | AC37: 852.5 | AD37: 103.2 | AE37: 209 | AF37: 901 | AG37: 4618 | AH37: 1194.2 | AI37: 367.5 | AJ37: 3.859 | AK37: 372.5 | AL37: 586.5 | AM37: 858.5 | AN37: 4744 | AO37: 1192.5 | AP37: 484.9
B38: 46036 | C38: 22.43 | D38: 14.93 | E38: 590.8 | F38: 353.4 | G38: 89.26 | H38: 2219 | I38: 10.87 | J38: 156 | K38: 20.27 | L38: 195.5 | M38: 328.2 | N38: 195.9 | O38: 75.64 | P38: 90.7 | Q38: 67.62 | R38: 206.95 | S38: 92 | T38: 29.5 | U38: 61.26 | V38: 40.1 | W38: 46034 | X38: 70.34 | Y38: 6237.2467 | Z38: 163.9 | AA38: 40.08 | AB38: 6135 | AC38: 841.5 | AD38: 103.6 | AE38: 209.5 | AF38: 886.8 | AG38: 4666 | AH38: 1202.4 | AI38: 362.2 | AJ38: 3.836 | AK38: 374 | AL38: 587.5 | AM38: 837.5 | AN38: 4770.5 | AO38: 1178.5 | AP38: 473.05
B39: 46037 | C39: 22.52 | D39: 14.83 | E39: 605.4 | F39: 363.9 | G39: 93.6 | H39: 2218 | I39: 10.735 | J39: 159 | K39: 20.55 | L39: 202.2 | M39: 335.6 | N39: 200 | O39: 77.32 | P39: 90 | Q39: 68.84 | R39: 214.1 | S39: 92.26 | T39: 29.86 | U39: 60.95 | V39: 40.59 | W39: 46035 | X39: 71 | Y39: 6199.1903 | Z39: 158.9 | AA39: 40.33 | AB39: 6214 | AC39: 834 | AD39: 102 | AE39: 207.5 | AF39: 894 | AG39: 4598 | AH39: 1212.8 | AI39: 362.4 | AJ39: 3.792 | AK39: 369.5 | AL39: 585 | AM39: 821.5 | AN39: 4774.5 | AO39: 1153.5 | AP39: 477.35
B40: 46038 | C40: 22.84 | D40: 14.95 | E40: 600.6 | F40: 367.1 | G40: 95.8 | H40: 2164 | I40: 10.585 | J40: 159.6 | K40: 20.2 | L40: 199.4 | M40: 334.8 | N40: 200.8 | O40: 75.74 | P40: 92.85 | Q40: 68.2 | R40: 216.1 | S40: 91.56 | T40: 29.91 | U40: 62.28 | V40: 40.53 | W40: 46036 | X40: 72.06 | Y40: 6193.1814 | Z40: 161.6 | AA40: 40.83 | AB40: 6355 | AC40: 845.5 | AD40: 102.9 | AE40: 209 | AF40: 889.6 | AG40: 4612 | AH40: 1213 | AI40: 366.1 | AJ40: 3.812 | AK40: 371.5 | AL40: 595.5 | AM40: 812 | AN40: 4831.5 | AO40: 1167 | AP40: 479.8
B41: 46041 | C41: 22.58 | D41: 14.8 | E41: 590.2 | F41: 362.7 | G41: 93.82 | H41: 2105 | I41: 10.185 | J41: 154.1 | K41: 19.7 | L41: 193 | M41: 319.4 | N41: 197 | O41: 74.84 | P41: 92.25 | Q41: 67.36 | R41: 205.8 | S41: 90.86 | T41: 29.01 | U41: 61.99 | V41: 40.46 | W41: 46037 | X41: 74.24 | Y41: 6155.1249 | Z41: 157.8 | AA41: 41.64 | AB41: 6468 | AC41: 862.5 | AD41: 104.5 | AE41: 212.5 | AF41: 894.2 | AG41: 4620 | AH41: 1236.8 | AI41: 362.2 | AJ41: 3.797 | AK41: 377.5 | AL41: 595 | AM41: 810 | AN41: 4780.5 | AO41: 1181 | AP41: 484.3
B42: 46042 | C42: 22.25 | D42: 14.49 | E42: 592.8 | F42: 357.3 | G42: 94.12 | H42: 2114 | I42: 9.892 | J42: 149.3 | K42: 19.84 | L42: 196.2 | M42: 319 | N42: 191.2 | O42: 72.48 | P42: 89.75 | Q42: 65.46 | R42: 212.45 | S42: 90.12 | T42: 28.44 | U42: 60.74 | V42: 40.11 | W42: 46038 | X42: 72.1 | Y42: 6125.0804 | Z42: 159.1 | AA42: 41.16 | AB42: 6347 | AC42: 860 | AD42: 104.5 | AE42: 213 | AF42: 889.4 | AG42: 4582 | AH42: 1232 | AI42: 363.9 | AJ42: 3.803 | AK42: 379.5 | AL42: 595 | AM42: 832.5 | AN42: 4761.5 | AO42: 1201.5 | AP42: 488.95
B43: 46043 | C43: 22.03 | D43: 14.52 | E43: 585.8 | F43: 361 | G43: 94.08 | H43: 2109 | I43: 10.17 | J43: 146.8 | K43: 20.36 | L43: 195.4 | M43: 319 | N43: 190 | O43: 74.68 | P43: 87.05 | Q43: 65.46 | R43: 208.75 | S43: 89.28 | T43: 28.97 | U43: 58.72 | V43: 39.69 | W43: 46041 | X43: 70.96 | Y43: 6125.0804 | Z43: 154.8 | AA43: 40.06 | AB43: 6339 | AC43: 845 | AD43: 104.5 | AE43: 215 | AF43: 872.4 | AG43: 4554 | AH43: 1238.8 | AI43: 361.1 | AJ43: 3.888 | AK43: 380.5 | AL43: 602 | AM43: 834 | AN43: 4756 | AO43: 1196 | AP43: 483
B44: 46044 | C44: 22.29 | D44: 14.46 | E44: 590 | F44: 374.7 | G44: 96.62 | H44: 2140 | I44: 10.515 | J44: 148.7 | K44: 20.83 | L44: 196.5 | M44: 321 | N44: 193.1 | O44: 78.08 | P44: 83.6 | Q44: 66.46 | R44: 208.65 | S44: 91.12 | T44: 29.68 | U44: 57.5 | V44: 40.25 | W44: 46042 | X44: 69.4 | Y44: 6115.0656 | Z44: 153.8 | AA44: 40 | AB44: 6314 | AC44: 844.5 | AD44: 103.5 | AE44: 214 | AF44: 912.2 | AG44: 4522 | AH44: 1229 | AI44: 372.9 | AJ44: 3.899 | AK44: 379.5 | AL44: 599 | AM44: 967.5 | AN44: 4775 | AO44: 1190.5 | AP44: 479.6
... B50: 46052 | C50: 22.35 | D50: 14.59 | E50: 578.6 | F50: 338 | G50: 100.45 | H50: 2158 | I50: 9.738 | J50: 141.9 | K50: 21.56 | L50: 195.6 | M50: 306.2 | N50: 196.5 | O50: 73.62 | P50: 83.65 | Q50: 67.04 | R50: 205.8 | S50: 93 | T50: 28.93 | U50: 54.05 | V50: 37.57 | W50: 46050 | X50: 72.26 | Y50: 5948.8191 | Z50: 144.3 | AA50: 41.86 | AB50: 6751 | AC50: 844.5 | AD50: 106 | AE50: 221.5 | AF50: 886.4 | AG50: 4492 | AH50: 1258.6 | AI50: 372.5 | AJ50: 3.98 | AK50: 385 | AL50: 633 | AM50: 952 | AN50: 4815.5 | AO50: 1230.5 | AP50: 479.8
B51: 46015 | C51: NULL | D51: 15.17 | E51: NULL | F51: NULL | G51: NULL | H51: 2313 | I51: NULL | J51: NULL | K51: NULL | L51: NULL | M51: NULL | N51: NULL | O51: NULL | P51: NULL | Q51: NULL | R51: NULL | S51: 92.3 | T51: NULL | U51: NULL | V51: NULL | W51: 46051 | X51: 70.66 | Y51: 6000.8963 | Z51: 142.9 | AA51: 40.75 | AB51: 6849 | AC51: 837.5 | AD51: 104.3 | AE51: 226 | AF51: 876.6 | AG51: 4454 | AH51: 1270 | AI51: 371.6 | AJ51: 4.091 | AK51: 391 | AL51: 632 | AM51: 945.5 | AN51: 4867.5 | AO51: 1230 | AP51: 479.6
B52: 46022 | C52: NULL | D52: 15.17 | E52: NULL | F52: NULL | G52: NULL | H52: 2268 | I52: NULL | J52: NULL | K52: NULL | L52: NULL | M52: NULL | N52: NULL | O52: NULL | P52: NULL | Q52: NULL | R52: NULL | S52: 92.76 | T52: NULL | U52: NULL | V52: NULL | W52: 46052 | X52: 71.02 | Y52: 6101.0448 | Z52: 143.9 | AA52: 40.96 | AB52: 6738 | AC52: 837 | AD52: 103.6 | AE52: 226 | AF52: 880 | AG52: 4464 | AH52: 1285.4 | AI52: 378.9 | AJ52: 4.108 | AK52: 389 | AL52: 633.5 | AM52: 943 | AN52: 4940.5 | AO52: 1234.5 | AP52: 486.2

Sheet S&P500 and STOXX Data
A1: =_xll.RDP.Data(".SP500;.STOXX","TR.PriceClose","SDate=2025-11-22 EDate=2026-01-31 Curn=EUR CH=IN RH=date",B2) -> #N/A
C2: .SP500 | D2: .STOXX
B3: 45985 | C3: 5820.4439 | D3: 562.88
B4: 45986 | C4: 5848.2879 | D4: 568.01
B5: 45987 | C5: 5876.0151 | D5: 574.21
B6: 45987 | C6: 5876.0151 | D6: NULL
B7: 45989 | C7: 5906.9269 | D7: 576.43
B8: 45992 | C8: 5867.9191 | D8: 575.27
B9: 45993 | C9: 5875.7173 | D9: 575.65
B10: 45994 | C10: 5869.5274 | D10: 576.22
B11: 45995 | C11: 5889.5115 | D11: 578.84
B12: 45996 | C12: 5901.4024 | D12: 578.77
B13: 45999 | C13: 5883.8874 | D13: 578.36
B14: 46000 | C14: 5884.3432 | D14: 577.77
B15: 46001 | C15: 5889.0781 | D15: 578.17
B16: 46002 | C16: 5879.1648 | D16: 581.34
B17: 46003 | C17: 5815.5166 | D17: 578.24
B18: 46006 | C18: 5800.3032 | D18: 582.54
... B26: 46015 | C26: 5885.5871 | D26: 588.7
B27: 46015 | C27: NULL | D27: 588.7
B28: 46017 | C28: 5887.3272 | D28: NULL
B29: 46020 | C29: 5866.2224 | D29: 589.25
B30: 46021 | C30: 5871.1154 | D30: 592.78
B31: 46022 | C31: 5828.4681 | D31: 592.19
B32: 46022 | C32: 5828.4681 | D32: 592.19
B33: 46024 | C33: 5852.4716 | D33: 596.14
B34: 46027 | C34: 5889.1058 | D34: 601.76
B35: 46028 | C35: 5942.3345 | D35: 605.28
B36: 46029 | C36: 5929.0217 | D36: 604.99
B37: 46030 | C37: 5937.0875 | D37: 603.83
B38: 46031 | C38: 5986.3367 | D38: 609.67
B39: 46034 | C39: 5980.3534 | D39: 610.95
B40: 46035 | C40: 5982.0574 | D40: 610.44
... B43: 46038 | C43: 5984.3008 | D43: 614.38
B44: 46038 | C44: 5984.3008 | D44: NULL
B45: 46042 | C45: 5797.3824 | D45: 602.8
B46: 46043 | C46: 5885.6642 | D46: 602.67
B47: 46044 | C47: 5881.6725 | D47: 608.86
B48: 46045 | C48: 5847.7712 | D48: 608.34
B49: 46048 | C49: 5850.8445 | D49: 609.57
...

Sheet S&P500 and STOXX PERFOMRMANCE
B1: .SP500 | C1: .STOXX | G1: DATE | H1: DATE | I1: S&P500 | J1: STOXX | M1: DATE | N1: S&P500 | O1: STOXX | P1: L/S Fund
A2: 45775 | B2: 4840.8592 | C2: 523.19 | G2: 45775 | H2: 45775 | I2: 4840.8592 | J2: 523.19 | M2: 45775 | N2: 1 | O2: 1 | P2: 1
A3: 45776 | B3: 4884.3524 | C3: 525.09 | G3: 45776 | H3: 45776 | I3: 4884.3524 | J3: 525.09 | M3: 45776 | N3: =I3/$I$2 -> 1.0089846 | O3: =J3/$J$2 -> 1.0036316 | P3: 0.99788387
A4: 45777 | B4: 4916.6488 | C4: 527.48 | G4: 45777 | H4: 45777 | I4: 4916.6488 | J4: 527.48 | M4: 45777 | N4: =I4/$I$2 -> 1.0156562 | O4: =J4/$J$2 -> 1.0081997 | P4: 0.9826644
A5: 45778 | B5: 4963.3638 | C5: 527.6 | G5: 45778 | H5: 45778 | I5: 4963.3638 | J5: 527.6 | M5: 45778 | N5: =I5/$I$2 -> 1.0253064 | O5: =J5/$J$2 -> 1.0084291 | P5: 0.98118699
A6: 45779 | B6: 5034.6975 | C6: 536.43 | G6: 45779 | H6: 45779 | I6: 5034.6975 | J6: 536.43 | M6: 45779 | N6: =I6/$I$2 -> 1.0400421 | O6: =J6/$J$2 -> 1.0253063 | P6: 0.99187886
A7: 45782 | B7: 4994.1464 | C7: 537.31 | G7: 45782 | H7: 45782 | I7: 4994.1464 | J7: 537.31 | M7: 45782 | N7: =I7/$I$2 -> 1.0316653 | O7: =J7/$J$2 -> 1.0269883 | P7: 0.99607989
A8: 45783 | B8: 4932.1716 | C8: 536.35 | G8: 45783 | H8: 45783 | I8: 4932.1716 | J8: 536.35 | M8: 45783 | N8: =I8/$I$2 -> 1.0188629 | O8: =J8/$J$2 -> 1.0251534 | P8: 0.99383103
A9: 45784 | B9: 4983.8555 | C9: 533.47 | G9: 45784 | H9: 45784 | I9: 4983.8555 | J9: 533.47 | M9: 45784 | N9: =I9/$I$2 -> 1.0295395 | O9: =J9/$J$2 -> 1.0196487 | P9: 0.99022202
A10: 45785 | B10: 5044.9274 | C10: 535.63 | G10: 45785 | H10: 45785 | I10: 5044.9274 | J10: 535.63 | M10: 45785 | N10: =I10/$I$2 -> 1.0421554 | O10: =J10/$J$2 -> 1.0237772 | P10: 0.99283465
A11: 45786 | B11: 5032.3978 | C11: 537.96 | G11: 45786 | H11: 45786 | I11: 5032.3978 | J11: 537.96 | M11: 45786 | N11: =I11/$I$2 -> 1.0395671 | O11: =J11/$J$2 -> 1.0282307 | P11: 1.0042642
A12: 45789 | B12: 5271.2226 | C12: 544.49 | G12: 45789 | H12: 45789 | I12: 5271.2226 | J12: 544.49 | M12: 45789 | N12: =I12/$I$2 -> 1.0889023 | O12: =J12/$J$2 -> 1.0407118 | P12: 0.99742439
A13: 45790 | B13: 5263.3435 | C13: 545.17 | G13: 45790 | H13: 45790 | I13: 5263.3435 | J13: 545.17 | M13: 45790 | N13: =I13/$I$2 -> 1.0872747 | O13: =J13/$J$2 -> 1.0420115 | P13: 1.0043449
A14: 45791 | B14: 5273.4506 | C14: 543.88 | G14: 45791 | H14: 45791 | I14: 5273.4506 | J14: 543.88 | M14: 45791 | N14: =I14/$I$2 -> 1.0893625 | O14: =J14/$J$2 -> 1.0395459 | P14: 1.010664
... A21: 45800 | B21: 5106.3032 | C21: 545.13 | G21: 45800 | H21: 45800 | I21: 5106.3032 | J21: 545.13 | M21: 45800 | N21: =I21/$I$2 -> 1.0548341 | O21: =J21/$J$2 -> 1.0419351 | P21: 1.0218083
G22: 45804 | H22: 45804 | I22: 5227.3582 | J22: 552.32 | M22: 45804 | N22: =I22/$I$2 -> 1.079841 | O22: =J22/$J$2 -> 1.0556777 | P22: 1.0335822
A23: 45804 | B23: 5227.3582 | C23: 552.32 | G23: 45805 | H23: 45805 | I23: 5214.7844 | J23: 548.93 | M23: 45805 | N23: =I23/$I$2 -> 1.0772436 | O23: =J23/$J$2 -> 1.0491982 | P23: 1.0383825
A24: 45805 | B24: 5214.7844 | C24: 548.93 | G24: 45806 | H24: 45806 | I24: 5199.342 | J24: 547.88 | M24: 45806 | N24: =I24/$I$2 -> 1.0740536 | O24: =J24/$J$2 -> 1.0471913 | P24: 1.0333235
A25: 45806 | B25: 5199.342 | C25: 547.88 | G25: 45807 | H25: 45807 | I25: 5209.9104 | J25: 548.67 | M25: 45807 | N25: =I25/$I$2 -> 1.0762367 | O25: =J25/$J$2 -> 1.0487012 | P25: 1.0335632
A26: 45807 | B26: 5209.9104 | C26: 548.67 | G26: 45810 | H26: 45810 | I26: 5188.3092 | J26: 547.92 | M26: 45810 | N26: =I26/$I$2 -> 1.0717745 | O26: =J26/$J$2 -> 1.0472677 | P26: 1.0458771
A27: 45810 | B27: 5188.3092 | C27: 547.92 | G27: 45811 | H27: 45811 | I27: 5250.9985 | J27: 548.44 | M27: 45811 | N27: =I27/$I$2 -> 1.0847245 | O27: =J27/$J$2 -> 1.0482616 | P27: 1.0477315
A28: 45811 | B28: 5250.9985 | C28: 548.44 | G28: 45812 | H28: 45812 | I28: 5229.7756 | J28: 551.02 | M28: 45812 | N28: =I28/$I$2 -> 1.0803404 | O28: =J28/$J$2 -> 1.0531929 | P28: 1.0379179
A29: 45812 | B29: 5229.7756 | C29: 551.02 | G29: 45813 | H29: 45813 | I29: 5189.882 | J29: 551.88 | M29: 45813 | N29: =I29/$I$2 -> 1.0720994 | O29: =J29/$J$2 -> 1.0548367 | P29: 1.049646
A30: 45813 | B30: 5189.882 | C30: 551.88 | G30: 45814 | H30: 45814 | I30: 5266.2117 | J30: 553.64 | M30: 45814 | N30: =I30/$I$2 -> 1.0878671 | O30: =J30/$J$2 -> 1.0582007 | P30: 1.052973
A31: 45814 | B31: 5266.2117 | C31: 553.64 | G31: 45817 | H31: 45817 | I31: 5259.1119 | J31: 553.24 | M31: 45817 | N31: =I31/$I$2 -> 1.0864005 | O31: =J31/$J$2 -> 1.0574361 | P31: 1.0489538
A32: 45817 | B32: 5259.1119 | C32: 553.24 | G32: 45818 | H32: 45818 | I32: 5286.5518 | J32: 553.12 | M32: 45818 | N32: =I32/$I$2 -> 1.0920689 | O32: =J32/$J$2 -> 1.0572068 | P32: 1.0297792
A33: 45818 | B33: 5286.5518 | C33: 553.12 | G33: 45819 | H33: 45819 | I33: 5242.6621 | J33: 551.64 | M33: 45819 | N33: =I33/$I$2 -> 1.0830024 | O33: =J33/$J$2 -> 1.054378 | P33: 1.0343832
A34: 45819 | B34: 5242.6621 | C34: 551.64 | G34: 45820 | H34: 45820 | I34: 5219.0506 | J34: 549.84 | M34: 45820 | N34: =I34/$I$2 -> 1.0781249 | O34: =J34/$J$2 -> 1.0509375 | P34: 1.037097
... A39: 45826 | B39: 5210.2908 | C39: 540.33 | G39: 45827 | H39: 45827 | I39: 5210.2908 | J39: 540.33 | M39: 45827 | N39: =I39/$I$2 -> 1.0763153 | O39: =J39/$J$2 -> 1.0327606 | P39: 1.0460842
A40: 45826 | B40: 5210.2908 | C40: NULL | G40: 45828 | H40: 45828 | I40: 5179.4879 | J40: 536.53 | M40: 45828 | N40: =I40/$I$2 -> 1.0699522 | O40: =J40/$J$2 -> 1.0254974 | P40: 1.0533587
A41: 45828 | B41: 5179.4879 | C41: 536.53 | G41: 45831 | H41: 45831 | I41: 5204.9068 | J41: 535.03 | M41: 45831 | N41: =I41/$I$2 -> 1.0752031 | O41: =J41/$J$2 -> 1.0226304 | P41: 1.0423171
A42: 45831 | B42: 5204.9068 | C42: 535.03 | G42: 45832 | H42: 45832 | I42: 5248.2313 | J42: 540.98 | M42: 45832 | N42: =I42/$I$2 -> 1.0841528 | O42: =J42/$J$2 -> 1.0340029 | P42: 1.0545769
A43: 45832 | B43: 5248.2313 | C43: 540.98 | G43: 45833 | H43: 45833 | I43: 5225.3078 | J43: 536.98 | M43: 45833 | N43: =I43/$I$2 -> 1.0794174 | O43: =J43/$J$2 -> 1.0263575 | P43: 1.0644144
A44: 45833 | B44: 5225.3078 | C44: 536.98 | G44: 45834 | H44: 45834 | I44: 5249.1591 | J44: 537.48 | M44: 45834 | N44: =I44/$I$2 -> 1.0843445 | O44: =J44/$J$2 -> 1.0273132 | P44: 1.0781776
A45: 45834 | B45: 5249.1591 | C45: 537.48 | G45: 45835 | H45: 45835 | I45: 5267.6072 | J45: 543.63 | M45: 45835 | N45: =I45/$I$2 -> 1.0881554 | O45: =J45/$J$2 -> 1.039068 | P45: 1.0800268
A46: 45835 | B46: 5267.6072 | C46: 543.63 | G46: 45838 | H46: 45838 | I46: 5264.6553 | J46: 541.37 | M46: 45838 | N46: =I46/$I$2 -> 1.0875456 | O46: =J46/$J$2 -> 1.0347484 | P46: 1.094584
A47: 45838 | B47: 5264.6553 | C47: 541.37 | G47: 45839 | H47: 45839 | I47: 5250.3316 | J47: 540.25 | M47: 45839 | N47: =I47/$I$2 -> 1.0845867 | O47: =J47/$J$2 -> 1.0326077 | P47: 1.0658502
A48: 45839 | B48: 5250.3316 | C48: 540.25 | G48: 45840 | H48: 45840 | I48: 5278.3609 | J48: 541.21 | M48: 45840 | N48: =I48/$I$2 -> 1.0903769 | O48: =J48/$J$2 -> 1.0344426 | P48: 1.0726144
A49: 45840 | B49: 5278.3609 | C49: 541.21 | G49: 45841 | H49: 45841 | I49: 5341.4043 | J49: 543.76 | M49: 45841 | N49: =I49/$I$2 -> 1.1034001 | O49: =J49/$J$2 -> 1.0393165 | P49: 1.0801061
A50: 45841 | B50: 5341.4043 | C50: 543.76 | G50: 45842 | H50: 45842 | I50: 5341.4043 | J50: 543.76 | M50: 45842 | N50: =I50/$I$2 -> 1.1034001 | O50: =J50/$J$2 -> 1.0393165 | P50: 1.0795118
...

Sheet EU PORTFOLIO
A1: Amount | B1: 5000
A8: Weights | B8: 0.05 | C8: 0.05 | D8: 0.00034145618 | E8: 0.012329728 | F8: 0.027417709 | G8: 0.00076568432 | H8: 0.023264253 | I8: 0.05 | J8: 0.038168433 | K8: 0.014232641 | L8: 0.015093703 | M8: 0.0073236691 | N8: 0.0096434122 | O8: 0.037464775 | P8: 0.0066656871 | Q8: 0.024609894 | R8: 0.009572552 | S8: 0.023106403 | T8: 0.05 | U8: 0.05 | W8: Weights | X8: 0.05 | Y8: 0.026681427 | Z8: 0.05 | AA8: 0.028622193 | AB8: 0.0083942697 | AC8: 0.0052007038 | AD8: 0.045609363 | AE8: 0.032804554 | AF8: 0.0057050022 | AG8: 0.014719709 | AH8: 0.013518898 | AI8: 0.05 | AJ8: 0.021450836 | AK8: 0.030350339 | AL8: 0.038083111 | AM8: 0.011932105 | AN8: 0.03852273 | AO8: 0.017874373 | AP8: 0.0073153623 | AQ8: 0.0032150242
B10: FBK.MI | C10: REDE.MC | D10: EVOG.ST | E10: EQTAB.ST | F10: PRY.MI | G10: CCL.L | H10: STERV.HE | I10: HEM.ST | J10: NESTE.HE | K10: LAGRb.ST | L10: LIFCOb.ST | M10: SAGAb.ST | N10: SSABb.ST | O10: HAGG.DE | P10: BALDb.ST | Q10: MYCR.ST | R10: URW.PA | S10: VALMT.HE | T10: R3NK.DE | U10: DNP.WA | X10: SYENS.BR | Y10: RKT.L | Z10: GALD.S | AA10: DTGGe.DE | AB10: RIO.L | AC10: HWDN.L | AD10: PHP.L | AE10: ALLN.S | AF10: INF.L | AG10: ITRK.L | AH10: HSBA.L | AI10: HLN.L | AJ10: KPN.AS | AK10: MOBN.S | AL10: SCMN.S | AM10: WISEa.L | AN10: ULVR.L | AO10: NG.L | AP10: BARC.L | AQ10: ORSTED.CO | AR10: STOXX Long Performance | AS10: STOXX600 Long Change Daily | AT10: STOXX Long Change Percentage Daily | AU10: STOXX Short Performance Treated as LONG | AV10: STOXX600 Short Portfolio Daily | AW10: EURO SHORT CORRECTLY | AX10: EURO Daily
A11: 45982 | B11: 20.61 | C11: 15.04 | D11: 632 | E11: 314 | F11: 80.8 | G11: 1808.5 | H11: 9.654 | I11: 175.1 | J11: 16.725 | K11: 207.2 | L11: 342.2 | M11: 198.9 | N11: 61.32 | O11: 72.5 | P11: 67.52 | Q11: 202.75 | R11: 89.4 | S11: 27.55 | T11: 50.86 | U11: 42.3 | W11: 45982 | X11: 68.54 | Y11: 5916.7716 | Z11: 147.7 | AA11: 35.55 | AB11: 5308 | AC11: 802 | AD11: 94.3 | AE11: 198.2 | AF11: 918.2 | AG11: 4834 | AH11: 1041.4 | AI11: 377.2 | AJ11: 3.93 | AK11: 354.5 | AL11: 574.5 | AM11: 874 | AN11: 4911.4944 | AO11: 1138.5 | AP11: 392.2 | AQ11: 140.89555 | AR11: {=SUMPRODUCT($B$162:$U$162,(B11:U11)/($B$11:$U$11))} -> 2500 | AS11: 0 | AT11: 1 | AU11: {=SUMPRODUCT($X$162:$AQ$162,(X11:AQ11)/($X$11:$AQ$11))} -> 2500 | AV11: 0 | AW11: 0 | AX11: 0
A12: 45985 | B12: 20.52 | C12: 15.22 | D12: 638 | E12: 320.6 | F12: 83 | G12: 1844 | H12: 9.86 | I12: 176.4 | J12: 16.1 | K12: 209 | L12: 343.8 | M12: 199.4 | N12: 63.22 | O12: 69.2 | P12: 68.06 | Q12: 209.1 | R12: 89.46 | S12: 27.78 | T12: 48.635 | U12: 41.96 | W12: 45985 | X12: 69.22 | Y12: 5856.6825 | Z12: 149.7 | AA12: 36.08 | AB12: 5355 | AC12: 811 | AD12: 94.05 | AE12: 199.8 | AF12: 915.8 | AG12: 4870 | AH12: 1048 | AI12: 371.8 | AJ12: 3.94 | AK12: 357 | AL12: 580.5 | AM12: 871 | AN12: 4844.0082 | AO12: 1116 | AP12: 400.6 | AQ12: 143.2855 | AR12: {=SUMPRODUCT($B$162:$U$162,(B12:U12)/($B$11:$U$11))} -> 2490.428 | AS12: =AR12-AR11 -> -9.5720131 | AT12: =AR12/AR11-1 -> -0.0038288052 | AU12: {=SUMPRODUCT($X$162:$AQ$162,(X12:AQ12)/($X$11:$AQ$11))} -> 2505.1204 | AV12: =AU12-AU11 -> 5.1203852 | AW12: =IF(AV12>0, -AV12, ABS(AV12)) -> -5.1203852 | AX12: =AS12+AW12 -> -14.692398
A13: 45986 | B13: 20.97 | C13: 15.22 | D13: 638.8 | E13: 323.2 | F13: 82.78 | G13: 1800 | H13: 10.04 | I13: 168.2 | J13: 15.965 | K13: 214.2 | L13: 347.2 | M13: 200 | N13: 64.52 | O13: 68.9 | P13: 67.8 | Q13: 208.65 | R13: 90 | S13: 28.21 | T13: 50.91 | U13: 41.99 | W13: 45986 | X13: 70.22 | Y13: 5878.7152 | Z13: 155.3 | AA13: 37.15 | AB13: 5400 | AC13: 834 | AD13: 95.2 | AE13: 199.8 | AF13: 937.6 | AG13: 4592 | AH13: 1050.6 | AI13: 374.5 | AJ13: 3.973 | AK13: 357 | AL13: 582.5 | AM13: 879 | AN13: 4876.1445 | AO13: 1123.5 | AP13: 410 | AQ13: 145.5087 | AR13: {=SUMPRODUCT($B$162:$U$162,(B13:U13)/($B$11:$U$11))} -> 2500.7977 | AS13: =AR13-AR12 -> 10.369707 | AT13: =AR13/AR12-1 -> 0.0041638255 | AU13: {=SUMPRODUCT($X$162:$AQ$162,(X13:AQ13)/($X$11:$AQ$11))} -> 2530.4252 | AV13: =AU13-AU12 -> 25.30482 | AW13: =IF(AV13>0, -AV13, ABS(AV13)) -> -25.30482 | AX13: =AS13+AW13 -> -14.935112
A14: 45987 | B14: 21 | C14: 15.26 | D14: 640 | E14: 329.9 | F14: 85.22 | G14: 1796.5 | H14: 10.005 | I14: 170.1 | J14: 16.5 | K14: 216.6 | L14: 351.2 | M14: 203 | N14: 66.32 | O14: 69 | P14: 68.38 | Q14: 215.6 | R14: 90.72 | S14: 28.12 | T14: 51.35 | U14: 41.81 | W14: 45987 | X14: 69.9 | Y14: 5900.7478 | Z14: 158.6 | AA14: 37.21 | AB14: 5461 | AC14: 834 | AD14: 96.35 | AE14: 200.5 | AF14: 945.6 | AG14: 4638 | AH14: 1064.4 | AI14: 370.8 | AJ14: 3.99 | AK14: 359 | AL14: 585.5 | AM14: 867 | AN14: 4842.937 | AO14: 1134.5 | AP14: 422.95 | AQ14: 148.73235 | AR14: {=SUMPRODUCT($B$162:$U$162,(B14:U14)/($B$11:$U$11))} -> 2525.217 | AS14: =AR14-AR13 -> 24.419343 | AT14: =AR14/AR13-1 -> 0.0097646216 | AU14: {=SUMPRODUCT($X$162:$AQ$162,(X14:AQ14)/($X$11:$AQ$11))} -> 2541.449 | AV14: =AU14-AU13 -> 11.023793 | AW14: =IF(AV14>0, -AV14, ABS(AV14)) -> -11.023793 | AX14: =AS14+AW14 -> 13.39555
A15: 45988 | B15: 21.09 | C15: 15.4 | D15: 650 | E15: 330.6 | F15: 85.44 | G15: 1839.5 | H15: 10.165 | I15: 171.2 | J15: 16.72 | K15: 216.4 | L15: 350 | M15: 203 | N15: 65.5 | O15: 69.7 | P15: 68.42 | Q15: 219 | R15: 91.58 | S15: 28.18 | T15: 51.08 | U15: 41.03 | W15: 45988 | X15: 69.86 | Y15: 5882.7211 | Z15: 159.5 | AA15: 37.04 | AB15: 5355 | AC15: 839.5 | AD15: 97.2 | AE15: 201 | AF15: 946.8 | AG15: 4634 | AH15: 1065 | AI15: 370 | AJ15: 3.987 | AK15: 357.5 | AL15: 583.5 | AM15: 870 | AN15: 4841.8658 | AO15: 1144 | AP15: 429.95 | AQ15: 148.73235 | AR15: {=SUMPRODUCT($B$162:$U$162,(B15:U15)/($B$11:$U$11))} -> 2532.962 | AS15: =AR15-AR14 -> 7.7449446 | AT15: =AR15/AR14-1 -> 0.0030670411 | AU15: {=SUMPRODUCT($X$162:$AQ$162,(X15:AQ15)/($X$11:$AQ$11))} -> 2543.2047 | AV15: =AU15-AU14 -> 1.7557335 | AW15: =IF(AV15>0, -AV15, ABS(AV15)) -> -1.7557335 | AX15: =AS15+AW15 -> 5.989211
A16: 45989 | B16: 21.15 | C16: 15.38 | D16: 645.2 | E16: 327 | F16: 86.3 | G16: 1813.5 | H16: 10.13 | I16: 175.5 | J16: 16.64 | K16: 216.2 | L16: 347.2 | M16: 202 | N16: 66.2 | O16: 68.35 | P16: 67.92 | Q16: 218 | R16: 91.62 | S16: 28.11 | T16: 50.45 | U16: 40.83 | W16: 45989 | X16: 70.26 | Y16: 5860.6884 | Z16: 160 | AA16: 36.47 | AB16: 5422 | AC16: 841 | AD16: 97.5 | AE16: 202 | AF16: 959.8 | AG16: 4626 | AH16: 1070.2 | AI16: 370.9 | AJ16: 3.94 | AK16: 359 | AL16: 576.5 | AM16: 883 | AN16: 4867.5748 | AO16: 1146.5 | AP16: 430.25 | AQ16: 148.84351 | AR16: {=SUMPRODUCT($B$162:$U$162,(B16:U16)/($B$11:$U$11))} -> 2529.6338 | AS16: =AR16-AR15 -> -3.3281438 | AT16: =AR16/AR15-1 -> -0.0013139336 | AU16: {=SUMPRODUCT($X$162:$AQ$162,(X16:AQ16)/($X$11:$AQ$11))} -> 2545.2381 | AV16: =AU16-AU15 -> 2.0333221 | AW16: =IF(AV16>0, -AV16, ABS(AV16)) -> -2.0333221 | AX16: =AS16+AW16 -> -5.3614658
A17: 45992 | B17: 20.85 | C17: 15.28 | D17: 653.4 | E17: 320.1 | F17: 84.82 | G17: 1805 | H17: 10.015 | I17: 169.6 | J17: 16.89 | K17: 214.2 | L17: 344.8 | M17: 199.1 | N17: 66.3 | O17: 66.2 | P17: 67.04 | Q17: 216.85 | R17: 91.24 | S17: 27.84 | T17: 48.07 | U17: 40.79 | W17: 45992 | X17: 69.74 | Y17: 6002.8993 | Z17: 158.1 | AA17: 35.99 | AB17: 5465 | AC17: 839.5 | AD17: 97.15 | AE17: 200 | AF17: 946.2 | AG17: 4614 | AH17: 1079.6 | AI17: 374.4 | AJ17: 3.943 | AK17: 361 | AL17: 572.5 | AM17: 876.5 | AN17: 4883.643 | AO17: 1144 | AP17: 429.6 | AQ17: 144.06362 | AR17: {=SUMPRODUCT($B$162:$U$162,(B17:U17)/($B$11:$U$11))} -> 2491.8845 | AS17: =AR17-AR16 -> -37.749351 | AT17: =AR17/AR16-1 -> -0.014922852 | AU17: {=SUMPRODUCT($X$162:$AQ$162,(X17:AQ17)/($X$11:$AQ$11))} -> 2540.5105 | AV17: =AU17-AU16 -> -4.7275607 | AW17: =IF(AV17>0, -AV17, ABS(AV17)) -> 4.7275607 | AX17: =AS17+AW17 -> -33.02179
A18: 45993 | B18: 20.73 | C18: 15.29 | D18: 641.2 | E18: 321.1 | F18: 84.76 | G18: 1813 | H18: 9.934 | I18: 165.9 | J18: 17.14 | K18: 213 | L18: 342.2 | M18: 197.2 | N18: 66.2 | O18: 68.15 | P18: 66.48 | Q18: 214.95 | R18: 91.26 | S18: 27.9 | T18: 48.965 | U18: 40.56 | W18: 45993 | X18: 68.62 | Y18: 5988.8785 | Z18: 158.1 | AA18: 35.35 | AB18: 5417 | AC18: 824.5 | AD18: 97.5 | AE18: 201 | AF18: 937.2 | AG18: 4600 | AH18: 1087.8 | AI18: 368.8 | AJ18: 3.956 | AK18: 360.5 | AL18: 568 | AM18: 877 | AN18: 4802.2311 | AO18: 1150.5 | AP18: 436.4 | AQ18: 139.17257 | AR18: {=SUMPRODUCT($B$162:$U$162,(B18:U18)/($B$11:$U$11))} -> 2492.7648 | AS18: =AR18-AR17 -> 0.8802844 | AT18: =AR18/AR17-1 -> 0.00035326051 | AU18: {=SUMPRODUCT($X$162:$AQ$162,(X18:AQ18)/($X$11:$AQ$11))} -> 2526.7458 | AV18: =AU18-AU17 -> -13.764689 | AW18: =IF(AV18>0, -AV18, ABS(AV18)) -> 13.764689 | AX18: =AS18+AW18 -> 14.644974
A19: 45994 | B19: 20.55 | C19: 15.24 | D19: 633.4 | E19: 320.8 | F19: 82.6 | G19: 1794.5 | H19: 10.21 | I19: 162 | J19: 17.655 | K19: 213.2 | L19: 344.4 | M19: 195.9 | N19: 66.9 | O19: 68.3 | P19: 65.62 | Q19: 215.8 | R19: 90.14 | S19: 28.28 | T19: 49.225 | U19: 39.4 | W19: 45994 | X19: 68.42 | Y19: 5932.7953 | Z19: 163.2 | AA19: 35.48 | AB19: 5504 | AC19: 817.5 | AD19: 97.45 | AE19: 200.5 | AF19: 947 | AG19: 4600 | AH19: 1070.2 | AI19: 361.1 | AJ19: 3.952 | AK19: 358 | AL19: 562.5 | AM19: 850.5 | AN19: 4770.0948 | AO19: 1143.5 | AP19: 433.35 | AQ19: 140.33975 | AR19: {=SUMPRODUCT($B$162:$U$162,(B19:U19)/($B$11:$U$11))} -> 2486.3602 | AS19: =AR19-AR18 -> -6.4046183 | AT19: =AR19/AR18-1 -> -0.0025692831 | AU19: {=SUMPRODUCT($X$162:$AQ$162,(X19:AQ19)/($X$11:$AQ$11))} -> 2521.1201 | AV19: =AU19-AU18 -> -5.625665 | AW19: =IF(AV19>0, -AV19, ABS(AV19)) -> 5.625665 | AX19: =AS19+AW19 -> -0.77895337
A20: 45995 | B20: 20.71 | C20: 15.02 | D20: 621.8 | E20: 324 | F20: 84.5 | G20: 1779 | H20: 10.4 | I20: 159.2 | J20: 17.365 | K20: 218.8 | L20: 352.4 | M20: 199.6 | N20: 67.66 | O20: 69.05 | P20: 66.66 | Q20: 221.65 | R20: 90.14 | S20: 28.87 | T20: 49.455 | U20: 38.63 | W20: 45995 | X20: 68.1 | Y20: 5914.7686 | Z20: 163.7 | AA20: 37.63 | AB20: 5494 | AC20: 827.5 | AD20: 97.6 | AE20: 200 | AF20: 940.8 | AG20: 4608 | AH20: 1074.4 | AI20: 359.5 | AJ20: 3.969 | AK20: 357.5 | AL20: 561 | AM20: 849.5 | AN20: 4743.3146 | AO20: 1142.5 | AP20: 439.2 | AQ20: 144.50826 | AR20: {=SUMPRODUCT($B$162:$U$162,(B20:U20)/($B$11:$U$11))} -> 2493.4362 | AS20: =AR20-AR19 -> 7.0760644 | AT20: =AR20/AR19-1 -> 0.0028459531 | AU20: {=SUMPRODUCT($X$162:$AQ$162,(X20:AQ20)/($X$11:$AQ$11))} -> 2527.9603 | AV20: =AU20-AU19 -> 6.8401471 | AW20: =IF(AV20>0, -AV20, ABS(AV20)) -> -6.8401471 | AX20: =AS20+AW20 -> 0.23591724
A21: 45996 | B21: 20.4 | C21: 15.2 | D21: 622.4 | E21: 329.8 | F21: 84.98 | G21: 1796.5 | H21: 10.3 | I21: 170.5 | J21: 18.305 | K21: 214.6 | L21: 352.6 | M21: 200.8 | N21: 67.8 | O21: 68.45 | P21: 66.92 | Q21: 219.55 | R21: 89.22 | S21: 28.86 | T21: 51.71 | U21: 38.38 | W21: 45996 | X21: 69.42 | Y21: 5976.8607 | Z21: 162.8 | AA21: 37.65 | AB21: 5500 | AC21: 824.5 | AD21: 96.85 | AE21: 197.4 | AF21: 948.6 | AG21: 4590 | AH21: 1062 | AI21: 360.6 | AJ21: 3.934 | AK21: 351.5 | AL21: 557.5 | AM21: 863.5 | AN21: 4773.3084 | AO21: 1134.5 | AP21: 434.4 | AQ21: 142.95202 | AR21: {=SUMPRODUCT($B$162:$U$162,(B21:U21)/($B$11:$U$11))} -> 2525.6229 | AS21: =AR21-AR20 -> 32.186712 | AT21: =AR21/AR20-1 -> 0.012908577 | AU21: {=SUMPRODUCT($X$162:$AQ$162,(X21:AQ21)/($X$11:$AQ$11))} -> 2524.8044 | AV21: =AU21-AU20 -> -3.1558464 | AW21: =IF(AV21>0, -AV21, ABS(AV21)) -> 3.1558464 | AX21: =AS21+AW21 -> 35.342559
A22: 45999 | B22: 20.45 | C22: 15.13 | D22: 630 | E22: 327.9 | F22: 85.96 | G22: 1788.5 | H22: 10.245 | I22: 177.3 | J22: 18.34 | K22: 213.6 | L22: 348.8 | M22: 198.6 | N22: 69 | O22: 69.95 | P22: 65.54 | Q22: 219.7 | R22: 90.74 | S22: 28.64 | T22: 54.57 | U22: 38.14 | W22: 45999 | X22: 69.02 | Y22: 5910.7627 | Z22: 164.5 | AA22: 37.5 | AB22: 5476 | AC22: 808.5 | AD22: 95.35 | AE22: 196.4 | AF22: 941.4 | AG22: 4532 | AH22: 1064.6 | AI22: 357.6 | AJ22: 3.901 | AK22: 351 | AL22: 555.5 | AM22: 861 | AN22: 4680 | AO22: 1135.5 | AP22: 437 | AQ22: 138.50561 | AR22: {=SUMPRODUCT($B$162:$U$162,(B22:U22)/($B$11:$U$11))} -> 2550.9781 | AS22: =AR22-AR21 -> 25.355149 | AT22: =AR22/AR21-1 -> 0.010039166 | AU22: {=SUMPRODUCT($X$162:$AQ$162,(X22:AQ22)/($X$11:$AQ$11))} -> 2510.245 | AV22: =AU22-AU21 -> -14.559393 | AW22: =IF(AV22>0, -AV22, ABS(AV22)) -> 14.559393 | AX22: =AS22+AW22 -> 39.914542
A23: 46000 | B23: 20.6 | C23: 15.05 | D23: 637.4 | E23: 329.7 | F23: 84.32 | G23: 1781.5 | H23: 10.17 | I23: 172.1 | J23: 18.045 | K23: 210.6 | L23: 342.8 | M23: 195.3 | N23: 68.92 | O23: 74.05 | P23: 64.78 | Q23: 216.75 | R23: 90.56 | S23: 28.35 | T23: 57.57 | U23: 39.5 | W23: 46000 | X23: 68.24 | Y23: 5926.7864 | Z23: 165.5 | AA23: 36.91 | AB23: 5528 | AC23: 808 | AD23: 95.2 | AE23: 195.4 | AF23: 942.6 | AG23: 4446 | AH23: 1068 | AI23: 354.2 | AJ23: 3.896 | AK23: 350 | AL23: 551.5 | AM23: 873 | AN23: 4846.5 | AO23: 1129 | AP23: 440 | AQ23: 136.06008 | AR23: {=SUMPRODUCT($B$162:$U$162,(B23:U23)/($B$11:$U$11))} -> 2564.2254 | AS23: =AR23-AR22 -> 13.247305 | AT23: =AR23/AR22-1 -> 0.0051930298 | AU23: {=SUMPRODUCT($X$162:$AQ$162,(X23:AQ23)/($X$11:$AQ$11))} -> 2507.9276 | AV23: =AU23-AU22 -> -2.3174941 | AW23: =IF(AV23>0, -AV23, ABS(AV23)) -> 2.3174941 | AX23: =AS23+AW23 -> 15.564799
... A58: 46052 | B58: 22.35 | C58: 14.59 | D58: 578.6 | E58: 338 | F58: 100.45 | G58: 2158 | H58: 9.738 | I58: 141.9 | J58: 21.56 | K58: 195.6 | L58: 306.2 | M58: 196.5 | N58: 73.62 | O58: 83.65 | P58: 67.04 | Q58: 205.8 | R58: 93 | S58: 28.93 | T58: 54.05 | U58: 37.57 | W58: 46052 | X58: 71.02 | Y58: 6101.0448 | Z58: 143.9 | AA58: 40.96 | AB58: 6738 | AC58: 837 | AD58: 103.6 | AE58: 226 | AF58: 880 | AG58: 4464 | AH58: 1285.4 | AI58: 378.9 | AJ58: 4.108 | AK58: 389 | AL58: 633.5 | AM58: 943 | AN58: 4940.5 | AO58: 1234.5 | AP58: 486.2 | AQ58: 160.62649 | AR58: {=SUMPRODUCT($B$162:$U$162,(B58:U58)/($B$11:$U$11))} -> 2584.223 | AS58: =AR58-AR57 -> -17.526508 | AT58: =AR58/AR57-1 -> -0.0067364317 | AU58: {=SUMPRODUCT($X$162:$AQ$162,(X58:AQ58)/($X$11:$AQ$11))} -> 2660.2128 | AV58: =AU58-AU57 -> 13.472884 | AW58: =IF(AV58>0, -AV58, ABS(AV58)) -> -13.472884 | AX58: =AS58+AW58 -> -30.999391
AR59: {=SUMPRODUCT($B$162:$U$162,(B59:U59)/($B$11:$U$11))} -> 0 | AS59: =AR59-AR58 -> -2584.223 | AT59: =AR59/AR58-1 -> -1 | AU59: {=SUMPRODUCT($X$162:$AQ$162,(X59:AQ59)/($X$11:$AQ$11))} -> 0 | AV59: =AU59-AU58 -> -2660.2128 | AW59: =IF(AV59>0, -AV59, ABS(AV59)) -> 2660.2128 | AX59: =AS59+AW59 -> 75.989852
AR60: {=SUMPRODUCT($B$162:$U$162,(B60:U60)/($B$11:$U$11))} -> 0 | AS60: =AR60-AR59 -> 0 | AT60: =AR60/AR59-1 -> #DIV/0! | AU60: {=SUMPRODUCT($X$162:$AQ$162,(X60:AQ60)/($X$11:$AQ$11))} -> 0 | AV60: =AU60-AU59 -> 0 | AW60: =IF(AV60>0, -AV60, ABS(AV60)) -> 0 | AX60: =AS60+AW60 -> 0
AR61: {=SUMPRODUCT($B$162:$U$162,(B61:U61)/($B$11:$U$11))} -> 0 | AS61: =AR61-AR60 -> 0 | AT61: =AR61/AR60-1 -> #DIV/0! | AU61: {=SUMPRODUCT($X$162:$AQ$162,(X61:AQ61)/($X$11:$AQ$11))} -> 0 | AV61: =AU61-AU60 -> 0 | AW61: =IF(AV61>0, -AV61, ABS(AV61)) -> 0 | AX61: =AS61+AW61 -> 0
AR62: {=SUMPRODUCT($B$162:$U$162,(B62:U62)/($B$11:$U$11))} -> 0 | AS62: =AR62-AR61 -> 0 | AT62: =AR62/AR61-1 -> #DIV/0! | AU62: {=SUMPRODUCT($X$162:$AQ$162,(X62:AQ62)/($X$11:$AQ$11))} -> 0 | AV62: =AU62-AU61 -> 0 | AW62: =IF(AV62>0, -AV62, ABS(AV62)) -> 0 | AX62: =AS62+AW62 -> 0
AR63: {=SUMPRODUCT($B$162:$U$162,(B63:U63)/($B$11:$U$11))} -> 0 | AS63: =AR63-AR62 -> 0 | AT63: =AR63/AR62-1 -> #DIV/0! | AU63: {=SUMPRODUCT($X$162:$AQ$162,(X63:AQ63)/($X$11:$AQ$11))} -> 0 | AV63: =AU63-AU62 -> 0 | AW63: =IF(AV63>0, -AV63, ABS(AV63)) -> 0 | AX63: =AS63+AW63 -> 0
AR64: {=SUMPRODUCT($B$162:$U$162,(B64:U64)/($B$11:$U$11))} -> 0 | AS64: =AR64-AR63 -> 0 | AT64: =AR64/AR63-1 -> #DIV/0! | AU64: {=SUMPRODUCT($X$162:$AQ$162,(X64:AQ64)/($X$11:$AQ$11))} -> 0 | AV64: =AU64-AU63 -> 0 | AW64: =IF(AV64>0, -AV64, ABS(AV64)) -> 0 | AX64: =AS64+AW64 -> 0
AR65: {=SUMPRODUCT($B$162:$U$162,(B65:U65)/($B$11:$U$11))} -> 0 | AS65: =AR65-AR64 -> 0 | AT65: =AR65/AR64-1 -> #DIV/0! | AU65: {=SUMPRODUCT($X$162:$AQ$162,(X65:AQ65)/($X$11:$AQ$11))} -> 0 | AV65: =AU65-AU64 -> 0 | AW65: =IF(AV65>0, -AV65, ABS(AV65)) -> 0 | AX65: =AS65+AW65 -> 0
AR66: {=SUMPRODUCT($B$162:$U$162,(B66:U66)/($B$11:$U$11))} -> 0 | AS66: =AR66-AR65 -> 0 | AT66: =AR66/AR65-1 -> #DIV/0! | AU66: {=SUMPRODUCT($X$162:$AQ$162,(X66:AQ66)/($X$11:$AQ$11))} -> 0 | AV66: =AU66-AU65 -> 0 | AW66: =IF(AV66>0, -AV66, ABS(AV66)) -> 0 | AX66: =AS66+AW66 -> 0
AR67: {=SUMPRODUCT($B$162:$U$162,(B67:U67)/($B$11:$U$11))} -> 0 | AS67: =AR67-AR66 -> 0 | AT67: =AR67/AR66-1 -> #DIV/0! | AU67: {=SUMPRODUCT($X$162:$AQ$162,(X67:AQ67)/($X$11:$AQ$11))} -> 0 | AV67: =AU67-AU66 -> 0 | AW67: =IF(AV67>0, -AV67, ABS(AV67)) -> 0 | AX67: =AS67+AW67 -> 0
AR68: {=SUMPRODUCT($B$162:$U$162,(B68:U68)/($B$11:$U$11))} -> 0 | AS68: =AR68-AR67 -> 0 | AT68: =AR68/AR67-1 -> #DIV/0! | AU68: {=SUMPRODUCT($X$162:$AQ$162,(X68:AQ68)/($X$11:$AQ$11))} -> 0 | AV68: =AU68-AU67 -> 0 | AW68: =IF(AV68>0, -AV68, ABS(AV68)) -> 0 | AX68: =AS68+AW68 -> 0
AR69: {=SUMPRODUCT($B$162:$U$162,(B69:U69)/($B$11:$U$11))} -> 0 | AS69: =AR69-AR68 -> 0 | AT69: =AR69/AR68-1 -> #DIV/0! | AU69: {=SUMPRODUCT($X$162:$AQ$162,(X69:AQ69)/($X$11:$AQ$11))} -> 0 | AV69: =AU69-AU68 -> 0 | AW69: =IF(AV69>0, -AV69, ABS(AV69)) -> 0 | AX69: =AS69+AW69 -> 0
AR70: {=SUMPRODUCT($B$162:$U$162,(B70:U70)/($B$11:$U$11))} -> 0 | AS70: =AR70-AR69 -> 0 | AT70: =AR70/AR69-1 -> #DIV/0! | AU70: {=SUMPRODUCT($X$162:$AQ$162,(X70:AQ70)/($X$11:$AQ$11))} -> 0 | AV70: =AU70-AU69 -> 0 | AW70: =IF(AV70>0, -AV70, ABS(AV70)) -> 0 | AX70: =AS70+AW70 -> 0
... AR156: {=SUMPRODUCT($B$162:$U$162,(B156:U156)/($B$11:$U$11))} -> 0 | AS156: =AR156-AR155 -> 0 | AT156: =AR156/AR155-1 -> #DIV/0! | AU156: {=SUMPRODUCT($X$162:$AQ$162,(X156:AQ156)/($X$11:$AQ$11))} -> 0 | AV156: =AU156-AU155 -> 0 | AW156: =IF(AV156>0, -AV156, ABS(AV156)) -> 0 | AX156: =AS156+AW156 -> 0
AX158: =SUM(AX11:AX156) -> -4.5474735e-13
A159: Performance | B159: =B58-B11 -> 1.74 | C159: =C58-C11 -> -0.45 | D159: =D58-D11 -> -53.4 | E159: =E58-E11 -> 24 | F159: =F58-F11 -> 19.65 | G159: =G58-G11 -> 349.5 | H159: =H58-H11 -> 0.084 | I159: =I58-I11 -> -33.2 | ... U159: =U58-U11 -> -4.73 | W159: Performance | X159: =X58-X11 -> 2.48 | Y159: =Y58-Y11 -> 184.27318 | Z159: =Z58-Z11 -> -3.8 | AA159: =AA58-AA11 -> 5.41 | AB159: =AB58-AB11 -> 1430 | AC159: =AC58-AC11 -> 35 | AD159: =AD58-AD11 -> 9.3 | AE159: =AE58-AE11 -> 27.8 | ... AQ159: =AQ58-AQ11 -> 19.730935
A160: Performance % | B160: =B58/B11 -> 1.084425 | C160: =C58/C11 -> 0.97007979 | D160: =D58/D11 -> 0.91550633 | E160: =E58/E11 -> 1.0764331 | F160: =F58/F11 -> 1.2431931 | G160: =G58/G11 -> 1.1932541 | H160: =H58/H11 -> 1.0087011 | I160: =I58/I11 -> 0.81039406 | ... U160: =U58/U11 -> 0.88817967 | W160: Performance % | X160: =X58/X11 -> 1.0361833 | Y160: =Y58/Y11 -> 1.0311442 | Z160: =Z58/Z11 -> 0.97427217 | AA160: =AA58/AA11 -> 1.15218 | AB160: =AB58/AB11 -> 1.2694047 | AC160: =AC58/AC11 -> 1.0436409 | AD160: =AD58/AD11 -> 1.0986214 | AE160: =AE58/AE11 -> 1.1402624 | ... AQ160: =AQ58/AQ11 -> 1.1400394
A162: Invested Amounts | B162: =B8*$B$1 -> 250 | C162: =C8*$B$1 -> 250 | D162: =D8*$B$1 -> 1.7072809 | E162: =E8*$B$1 -> 61.648642 | F162: =F8*$B$1 -> 137.08855 | G162: =G8*$B$1 -> 3.8284216 | H162: =H8*$B$1 -> 116.32126 | I162: =I8*$B$1 -> 250 | ... U162: =U8*$B$1 -> 250 | W162: Invested Amounts | X162: =X8*$B$1 -> 250 | Y162: =Y8*$B$1 -> 133.40713 | Z162: =Z8*$B$1 -> 250 | AA162: =AA8*$B$1 -> 143.11096 | AB162: =AB8*$B$1 -> 41.971348 | AC162: =AC8*$B$1 -> 26.003519 | AD162: =AD8*$B$1 -> 228.04681 | AE162: =AE8*$B$1 -> 164.02277 | ... AQ162: =AQ8*$B$1 -> 16.075121
A163: Our current holdings | B163: =B160*B162 -> 271.10626 | C163: =C160*C162 -> 242.51995 | D163: =D160*D162 -> 1.5630265 | E163: =E160*E162 -> 66.36064 | F163: =F160*F162 -> 170.42753 | G163: =G160*G162 -> 4.5682797 | H163: =H160*H162 -> 117.33338 | I163: =I160*I162 -> 202.59852 | ... U163: =U160*U162 -> 222.04492 | W163: Our current holdings | X163: =X162*X160 -> 259.04581 | Y163: =Y162*Y160 -> 137.56199 | Z163: =Z162*Z160 -> 243.56804 | AA163: =AA162*AA160 -> 164.88959 | AB163: =AB162*AB160 -> 53.278626 | AC163: =AC162*AC160 -> 27.138336 | AD163: =AD162*AD160 -> 250.53712 | AE163: =AE162*AE160 -> 187.02899 | ... AQ163: =AQ162*AQ160 -> 18.326272
A164: Profit/Loss Performance | B164: =B163-B162 -> 21.106259 | C164: =C163-C162 -> -7.4800532 | D164: =D163-D162 -> -0.14425443 | E164: =E163-E162 -> 4.7119981 | F164: =F163-F162 -> 33.338984 | G164: =G163-G162 -> 0.73985809 | H164: =H163-H162 -> 1.0121179 | I164: =I163-I162 -> -47.401485 | ... U164: =U163-U162 -> -27.955083 | W164: Profit/Loss Performance | X164: =X162-X163 -> -9.0458127 | Y164: =Y162-Y163 -> -4.1548599 | Z164: =Z162-Z163 -> 6.4319567 | AA164: =AA162-AA163 -> -21.77863 | AB164: =AB162-AB163 -> -11.307277 | AC164: =AC162-AC163 -> -1.1348169 | AD164: =AD162-AD163 -> -22.490301 | AE164: =AE162-AE163 -> -23.006221 | ... AQ164: =AQ162-AQ163 -> -2.2511511
A165: Total Performance | B165: =SUM(B164:U164) -> 84.22296 | W165: Total Performance | X165: =SUM(X164:AQ164) -> -160.21281
A167: Total Invested | B167: =SUM(B162:U162) -> 2500 | W167: Total Invested | X167: =SUM(X162:AQ162) -> 2500
W170: Total Performance of EU | X170: =B165+X165 -> -75.989852

Sheet US PORTFOLIO
A1: Amount | B1: 5000
A8: Weights | B8: 0.013963003 | C8: 0.0084375992 | D8: 0.014382155 | E8: 0.027929285 | F8: 0.05 | G8: 0.031147719 | H8: 0.010740274 | I8: 0.013545965 | J8: 0.05 | K8: 0.03441597 | L8: 0.017828262 | M8: 0.010375281 | N8: 0.041767386 | O8: 0.039504341 | P8: 0.02334746 | Q8: 0.039566379 | R8: 0.014625218 | S8: 0.028465868 | T8: 0.014086743 | U8: 0.015871091 | W8: Weights | X8: 0.05 | Y8: 0.022884873 | Z8: 0.0091966185 | AA8: 0.010915154 | AB8: 0.017349028 | AC8: 0.01956786 | AD8: 0.05 | AE8: 0.011248738 | AF8: 0.044573061 | AG8: 0.0074261904 | AH8: 0.034234252 | AI8: 0.005341556 | AJ8: 0.030657968 | AK8: 0.0071577772 | AL8: 0.027381131 | AM8: 0.05 | AN8: 0.020692802 | AO8: 0.014235109 | AP8: 0.037878758 | AQ8: 0.029259123
B10: APP.OQ | C10: EPAM.N | D10: LULU.OQ | E10: EXR.N | F10: ERIE.OQ | G10: ACGL.OQ | H10: TPL.N | I10: BLDR.N | J10: SW.N | K10: HII.N | L10: EL.N | M10: DXCM.OQ | N10: REGN.OQ | O10: AIZ.N | P10: DECK.N | Q10: NEE.N | R10: MOH.N | S10: SBAC.OQ | T10: ODFL.OQ | U10: SMCI.OQ | X10: EXPD.N | Y10: SYY.N | Z10: HST.OQ | AA10: FCX.N | AB10: PLTR.OQ | AC10: AXP.N | AD10: JNJ.N | AE10: SPG.N | AF10: L.N | AG10: OXY.N | AH10: OMC.N | AI10: WYNN.OQ | AJ10: MGM.N | AK10: MAR.OQ | AL10: WFC.N | AM10: DTE.N | AN10: MCHP.OQ | AO10: MRNA.OQ | AP10: BRKb.N | AQ10: COP.N | AR10: US LONG Performance | AS10: US LONG Change Daily | AT10: US LONG Change Percentage Daily | AU10: US SHORT Performance Treated as LONG | AV10: US Short Portfolio Daily Treated as LONG | AW10: US SHORT CORRECTLY | AX10: US Daily | AY10: US Daily EUR
